Workbook

Sheet Summary
A1: AR Workbench – Requirements Test Report
A3: Requirement source | B3: AR_Workbench_Developer_Handoff_v1.0.docx (v1.0, 29 Sep 2026); mockup LRN_Denial_AR_Workbench_Demo_Account.html
A4: Application | B4: https://www.lrnanalytics.com/ARWBTest/ (Test) – lab Inhealth_DTR
A5: Tested as | B5: Phase 1: ARWBInhealthSA (System Administrator). Phase 2 role workflow: ARAgent1, QA1, TeamLead, RCMManager, ClinicViewer (Insight Family Practice), AccountManager (Client Viewer)
A6: Test date | B6: 15 Oct 2026
A7: Data snapshot | B7: Sync run #3, 08 Oct 2026 – 84,074 claims / 151,186 CPT lines
A8: Method | B8: Phase 1 read-only UI walkthrough + API reconciliation of all 84,074 claims. Phase 2 (user-approved) end-to-end role workflows on 10 test claims — see 'Role Workflow Tests'.
A10: Status | B10: # Test Cases | C10: % of Total
A11: Pass | B11: =COUNTIF('Test Cases'!$J$2:$J$69,A11) -> 34 | C11: =IFERROR(B11/$B$17,0) -> 0.5
A12: Fail | B12: =COUNTIF('Test Cases'!$J$2:$J$69,A12) -> 12 | C12: =IFERROR(B12/$B$17,0) -> 0.17647059
A13: Partial | B13: =COUNTIF('Test Cases'!$J$2:$J$69,A13) -> 14 | C13: =IFERROR(B13/$B$17,0) -> 0.20588235
A14: Blocked | B14: =COUNTIF('Test Cases'!$J$2:$J$69,A14) -> 3 | C14: =IFERROR(B14/$B$17,0) -> 0.044117647
A15: Not Executed | B15: =COUNTIF('Test Cases'!$J$2:$J$69,A15) -> 4 | C15: =IFERROR(B15/$B$17,0) -> 0.058823529
A16: N/A (Phase 2) | B16: =COUNTIF('Test Cases'!$J$2:$J$69,A16) -> 1 | C16: =IFERROR(B16/$B$17,0) -> 0.014705882
A17: Total | B17: =SUM(B11:B16) -> 68 | C17: =IFERROR(B17/B17,0) -> 1
A18: Pass rate (of executed) | B18: =IFERROR(B11/(B11+B12+B13),0) -> 0.56666667 | C18: Executed = Pass + Fail + Partial
A21: Module | B21: Total | C21: Pass | D21: Fail | E21: Partial | F21: Blocked | G21: Not Executed | H21: N/A (Phase 2)
A22: Data Sync & Grain | B22: =COUNTIF('Test Cases'!$B$2:$B$69,A22) -> 3 | C22: =COUNTIFS('Test Cases'!$B$2:$B$69,$A22,'Test Cases'!$J$2:$J$69,"Pass") -> 3 | D22: =COUNTIFS('Test Cases'!$B$2:$B$69,$A22,'Test Cases'!$J$2:$J$69,"Fail") -> 0 | E22: =COUNTIFS('Test Cases'!$B$2:$B$69,$A22,'Test Cases'!$J$2:$J$69,"Partial") -> 0 | F22: =COUNTIFS('Test Cases'!$B$2:$B$69,$A22,'Test Cases'!$J$2:$J$69,"Blocked") -> 0 | G22: =COUNTIFS('Test Cases'!$B$2:$B$69,$A22,'Test Cases'!$J$2:$J$69,"Not Executed") -> 0 | H22: =COUNTIFS('Test Cases'!$B$2:$B$69,$A22,'Test Cases'!$J$2:$J$69,"N/A (Phase 2)") -> 0
A23: Denial Insights | B23: =COUNTIF('Test Cases'!$B$2:$B$69,A23) -> 5 | C23: =COUNTIFS('Test Cases'!$B$2:$B$69,$A23,'Test Cases'!$J$2:$J$69,"Pass") -> 2 | D23: =COUNTIFS('Test Cases'!$B$2:$B$69,$A23,'Test Cases'!$J$2:$J$69,"Fail") -> 1 | E23: =COUNTIFS('Test Cases'!$B$2:$B$69,$A23,'Test Cases'!$J$2:$J$69,"Partial") -> 2 | F23: =COUNTIFS('Test Cases'!$B$2:$B$69,$A23,'Test Cases'!$J$2:$J$69,"Blocked") -> 0 | G23: =COUNTIFS('Test Cases'!$B$2:$B$69,$A23,'Test Cases'!$J$2:$J$69,"Not Executed") -> 0 | H23: =COUNTIFS('Test Cases'!$B$2:$B$69,$A23,'Test Cases'!$J$2:$J$69,"N/A (Phase 2)") -> 0
A24: Claim Detail | B24: =COUNTIF('Test Cases'!$B$2:$B$69,A24) -> 3 | C24: =COUNTIFS('Test Cases'!$B$2:$B$69,$A24,'Test Cases'!$J$2:$J$69,"Pass") -> 1 | D24: =COUNTIFS('Test Cases'!$B$2:$B$69,$A24,'Test Cases'!$J$2:$J$69,"Fail") -> 0 | E24: =COUNTIFS('Test Cases'!$B$2:$B$69,$A24,'Test Cases'!$J$2:$J$69,"Partial") -> 2 | F24: =COUNTIFS('Test Cases'!$B$2:$B$69,$A24,'Test Cases'!$J$2:$J$69,"Blocked") -> 0 | G24: =COUNTIFS('Test Cases'!$B$2:$B$69,$A24,'Test Cases'!$J$2:$J$69,"Not Executed") -> 0 | H24: =COUNTIFS('Test Cases'!$B$2:$B$69,$A24,'Test Cases'!$J$2:$J$69,"N/A (Phase 2)") -> 0
A25: AR Queue Logic | B25: =COUNTIF('Test Cases'!$B$2:$B$69,A25) -> 12 | C25: =COUNTIFS('Test Cases'!$B$2:$B$69,$A25,'Test Cases'!$J$2:$J$69,"Pass") -> 10 | D25: =COUNTIFS('Test Cases'!$B$2:$B$69,$A25,'Test Cases'!$J$2:$J$69,"Fail") -> 1 | E25: =COUNTIFS('Test Cases'!$B$2:$B$69,$A25,'Test Cases'!$J$2:$J$69,"Partial") -> 1 | F25: =COUNTIFS('Test Cases'!$B$2:$B$69,$A25,'Test Cases'!$J$2:$J$69,"Blocked") -> 0 | G25: =COUNTIFS('Test Cases'!$B$2:$B$69,$A25,'Test Cases'!$J$2:$J$69,"Not Executed") -> 0 | H25: =COUNTIFS('Test Cases'!$B$2:$B$69,$A25,'Test Cases'!$J$2:$J$69,"N/A (Phase 2)") -> 0
A26: Configuration | B26: =COUNTIF('Test Cases'!$B$2:$B$69,A26) -> 1 | C26: =COUNTIFS('Test Cases'!$B$2:$B$69,$A26,'Test Cases'!$J$2:$J$69,"Pass") -> 0 | D26: =COUNTIFS('Test Cases'!$B$2:$B$69,$A26,'Test Cases'!$J$2:$J$69,"Fail") -> 0 | E26: =COUNTIFS('Test Cases'!$B$2:$B$69,$A26,'Test Cases'!$J$2:$J$69,"Partial") -> 1 | F26: =COUNTIFS('Test Cases'!$B$2:$B$69,$A26,'Test Cases'!$J$2:$J$69,"Blocked") -> 0 | G26: =COUNTIFS('Test Cases'!$B$2:$B$69,$A26,'Test Cases'!$J$2:$J$69,"Not Executed") -> 0 | H26: =COUNTIFS('Test Cases'!$B$2:$B$69,$A26,'Test Cases'!$J$2:$J$69,"N/A (Phase 2)") -> 0
A27: Roles & Access | B27: =COUNTIF('Test Cases'!$B$2:$B$69,A27) -> 3 | C27: =COUNTIFS('Test Cases'!$B$2:$B$69,$A27,'Test Cases'!$J$2:$J$69,"Pass") -> 0 | D27: =COUNTIFS('Test Cases'!$B$2:$B$69,$A27,'Test Cases'!$J$2:$J$69,"Fail") -> 1 | E27: =COUNTIFS('Test Cases'!$B$2:$B$69,$A27,'Test Cases'!$J$2:$J$69,"Partial") -> 2 | F27: =COUNTIFS('Test Cases'!$B$2:$B$69,$A27,'Test Cases'!$J$2:$J$69,"Blocked") -> 0 | G27: =COUNTIFS('Test Cases'!$B$2:$B$69,$A27,'Test Cases'!$J$2:$J$69,"Not Executed") -> 0 | H27: =COUNTIFS('Test Cases'!$B$2:$B$69,$A27,'Test Cases'!$J$2:$J$69,"N/A (Phase 2)") -> 0
A28: Denial Logic | B28: =COUNTIF('Test Cases'!$B$2:$B$69,A28) -> 6 | C28: =COUNTIFS('Test Cases'!$B$2:$B$69,$A28,'Test Cases'!$J$2:$J$69,"Pass") -> 3 | D28: =COUNTIFS('Test Cases'!$B$2:$B$69,$A28,'Test Cases'!$J$2:$J$69,"Fail") -> 1 | E28: =COUNTIFS('Test Cases'!$B$2:$B$69,$A28,'Test Cases'!$J$2:$J$69,"Partial") -> 0 | F28: =COUNTIFS('Test Cases'!$B$2:$B$69,$A28,'Test Cases'!$J$2:$J$69,"Blocked") -> 1 | G28: =COUNTIFS('Test Cases'!$B$2:$B$69,$A28,'Test Cases'!$J$2:$J$69,"Not Executed") -> 0 | H28: =COUNTIFS('Test Cases'!$B$2:$B$69,$A28,'Test Cases'!$J$2:$J$69,"N/A (Phase 2)") -> 1
A29: Weekly Re-Sync | B29: =COUNTIF('Test Cases'!$B$2:$B$69,A29) -> 5 | C29: =COUNTIFS('Test Cases'!$B$2:$B$69,$A29,'Test Cases'!$J$2:$J$69,"Pass") -> 0 | D29: =COUNTIFS('Test Cases'!$B$2:$B$69,$A29,'Test Cases'!$J$2:$J$69,"Fail") -> 0 | E29: =COUNTIFS('Test Cases'!$B$2:$B$69,$A29,'Test Cases'!$J$2:$J$69,"Partial") -> 1 | F29: =COUNTIFS('Test Cases'!$B$2:$B$69,$A29,'Test Cases'!$J$2:$J$69,"Blocked") -> 1 | G29: =COUNTIFS('Test Cases'!$B$2:$B$69,$A29,'Test Cases'!$J$2:$J$69,"Not Executed") -> 3 | H29: =COUNTIFS('Test Cases'!$B$2:$B$69,$A29,'Test Cases'!$J$2:$J$69,"N/A (Phase 2)") -> 0
A30: Auto Adjustments | B30: =COUNTIF('Test Cases'!$B$2:$B$69,A30) -> 3 | C30: =COUNTIFS('Test Cases'!$B$2:$B$69,$A30,'Test Cases'!$J$2:$J$69,"Pass") -> 3 | D30: =COUNTIFS('Test Cases'!$B$2:$B$69,$A30,'Test Cases'!$J$2:$J$69,"Fail") -> 0 | E30: =COUNTIFS('Test Cases'!$B$2:$B$69,$A30,'Test Cases'!$J$2:$J$69,"Partial") -> 0 | F30: =COUNTIFS('Test Cases'!$B$2:$B$69,$A30,'Test Cases'!$J$2:$J$69,"Blocked") -> 0 | G30: =COUNTIFS('Test Cases'!$B$2:$B$69,$A30,'Test Cases'!$J$2:$J$69,"Not Executed") -> 0 | H30: =COUNTIFS('Test Cases'!$B$2:$B$69,$A30,'Test Cases'!$J$2:$J$69,"N/A (Phase 2)") -> 0
A31: Financial Fields | B31: =COUNTIF('Test Cases'!$B$2:$B$69,A31) -> 5 | C31: =COUNTIFS('Test Cases'!$B$2:$B$69,$A31,'Test Cases'!$J$2:$J$69,"Pass") -> 0 | D31: =COUNTIFS('Test Cases'!$B$2:$B$69,$A31,'Test Cases'!$J$2:$J$69,"Fail") -> 3 | E31: =COUNTIFS('Test Cases'!$B$2:$B$69,$A31,'Test Cases'!$J$2:$J$69,"Partial") -> 1 | F31: =COUNTIFS('Test Cases'!$B$2:$B$69,$A31,'Test Cases'!$J$2:$J$69,"Blocked") -> 1 | G31: =COUNTIFS('Test Cases'!$B$2:$B$69,$A31,'Test Cases'!$J$2:$J$69,"Not Executed") -> 0 | H31: =COUNTIFS('Test Cases'!$B$2:$B$69,$A31,'Test Cases'!$J$2:$J$69,"N/A (Phase 2)") -> 0
A32: Follow-Up | B32: =COUNTIF('Test Cases'!$B$2:$B$69,A32) -> 2 | C32: =COUNTIFS('Test Cases'!$B$2:$B$69,$A32,'Test Cases'!$J$2:$J$69,"Pass") -> 2 | D32: =COUNTIFS('Test Cases'!$B$2:$B$69,$A32,'Test Cases'!$J$2:$J$69,"Fail") -> 0 | E32: =COUNTIFS('Test Cases'!$B$2:$B$69,$A32,'Test Cases'!$J$2:$J$69,"Partial") -> 0 | F32: =COUNTIFS('Test Cases'!$B$2:$B$69,$A32,'Test Cases'!$J$2:$J$69,"Blocked") -> 0 | G32: =COUNTIFS('Test Cases'!$B$2:$B$69,$A32,'Test Cases'!$J$2:$J$69,"Not Executed") -> 0 | H32: =COUNTIFS('Test Cases'!$B$2:$B$69,$A32,'Test Cases'!$J$2:$J$69,"N/A (Phase 2)") -> 0
A33: Attachments | B33: =COUNTIF('Test Cases'!$B$2:$B$69,A33) -> 5 | C33: =COUNTIFS('Test Cases'!$B$2:$B$69,$A33,'Test Cases'!$J$2:$J$69,"Pass") -> 0 | D33: =COUNTIFS('Test Cases'!$B$2:$B$69,$A33,'Test Cases'!$J$2:$J$69,"Fail") -> 3 | E33: =COUNTIFS('Test Cases'!$B$2:$B$69,$A33,'Test Cases'!$J$2:$J$69,"Partial") -> 1 | F33: =COUNTIFS('Test Cases'!$B$2:$B$69,$A33,'Test Cases'!$J$2:$J$69,"Blocked") -> 0 | G33: =COUNTIFS('Test Cases'!$B$2:$B$69,$A33,'Test Cases'!$J$2:$J$69,"Not Executed") -> 1 | H33: =COUNTIFS('Test Cases'!$B$2:$B$69,$A33,'Test Cases'!$J$2:$J$69,"N/A (Phase 2)") -> 0
... A39: Export / Import | B39: =COUNTIF('Test Cases'!$B$2:$B$69,A39) -> 1 | C39: =COUNTIFS('Test Cases'!$B$2:$B$69,$A39,'Test Cases'!$J$2:$J$69,"Pass") -> 0 | D39: =COUNTIFS('Test Cases'!$B$2:$B$69,$A39,'Test Cases'!$J$2:$J$69,"Fail") -> 0 | E39: =COUNTIFS('Test Cases'!$B$2:$B$69,$A39,'Test Cases'!$J$2:$J$69,"Partial") -> 1 | F39: =COUNTIFS('Test Cases'!$B$2:$B$69,$A39,'Test Cases'!$J$2:$J$69,"Blocked") -> 0 | G39: =COUNTIFS('Test Cases'!$B$2:$B$69,$A39,'Test Cases'!$J$2:$J$69,"Not Executed") -> 0 | H39: =COUNTIFS('Test Cases'!$B$2:$B$69,$A39,'Test Cases'!$J$2:$J$69,"N/A (Phase 2)") -> 0
A40: Total | B40: =SUM(B22:B39) -> 68 | C40: =SUM(C22:C39) -> 34 | D40: =SUM(D22:D39) -> 12 | E40: =SUM(E22:E39) -> 14 | F40: =SUM(F22:F39) -> 3 | G40: =SUM(G22:G39) -> 4 | H40: =SUM(H22:H39) -> 1
A43: Key findings
A44: 1. Queue classification engine is correct: all 84,074 claims sit in exactly one queue and every Closed, Patient AR, Non-Responder, Denied and Partially Paid/Adjusted rule reconciles with zero exceptions.
A45: 2. Work-queue feed and 'Claims Awaiting Assignment' KPI include Non-Collectible, Unbilled (and for the KPI, Closed/Patient AR) claims — contrary to §3.2 (DEF-05, DEF-06).
A46: 3. Two conflicting Non-Collectible lists exist (Workbench list vs Denial Code Master) — needs a single source of truth (DEF-07).
A47: 4. Financial fields not functional: Revenue Expectation is $0 for every claim (no fee schedule), so Potential Recovery / Recovery Status are blocked; Recovered Amount includes adjustments (DEF-11, DEF-12).
A48: 5. Attachments on follow-ups, document categories and the Document Vault are not built (DEF-13, DEF-14).
A49: 6. 48% of denied claims fall to 'Other' because 50 codes (incl. 216) are unmapped — waiting on business categorization (DEF-09).
A50: 7. CRITICAL: client users (Clinic & Client Viewer) can open claim pages directly and read internal agent/QA notes (DEF-15).
A51: 8. Role workflows largely work end-to-end: assignment, QA approve/reject/rework, write-off approval, CIP two-level approval, client response with re-escalation and return to agent, escalation/reassignment requests (30 role steps, see 'Role Workflow Tests').
...

Sheet Test Cases
A1: Test Case ID | B1: Module | C1: Requirement Ref | D1: Priority | E1: Test Scenario | F1: Test Data / Pre-conditions | G1: Test Steps | H1: Expected Result | I1: Actual Result | J1: Status | K1: Defect / Obs Ref
A2: TC-001 | B2: Data Sync & Grain | C2: §2.1 / Feature #1 | D2: High | E2: Full claim-level master file is synced for the lab | F2: Lab Inhealth_DTR; Data Processing run #3 (R20261005INH3267 ... 09.22–09.28.2026.csv) | G2: 1. Open Data Processing. 2. Review Run history and source counters. 3. Reconcile claim count to queue totals via API. | H2: Every claim in the claim-level master file is loaded (not only insight-linked claims); line-level file also read. | I2: Run #3 succeeded: 84,074 claims (1,206 new, 1,802 updated, 81,066 unchanged, 0 dropped); 151,186 CPT lines read. 84,074 = sum of all queue counts. Header field 'Master File Loaded' shows '—'. | J2: Pass | K2: OBS-01
A3: TC-002 | B3: Data Sync & Grain | C3: §2.1 | D3: Medium | E3: Sync cadence is weekly and aligned with master refresh | F3: Run history; Nightly Queue Snapshots | G3: 1. Review run history dates. 2. Review nightly snapshot table. | H3: Weekly sync runs recorded; nightly recalculation of aging / TFL / re-follow-up. | I3: Syncs on Sep 30 and Oct 08, 2026; nightly snapshots Oct 06–Oct 15 present. | J3: Pass
A4: TC-003 | B4: Data Sync & Grain | C4: §2.1, §3 | D4: High | E4: Every list, queue and count is at claim grain; each claim sits in exactly one financial queue | F4: All 84,074 claims pulled via claims API (read-only) | G4: 1. Pull all claims. 2. Check unique claim keys. 3. Sum queue/sub-queue counts. | H4: Unique claim count = total; each claim in exactly one queue. | I4: 84,074 records, 84,074 unique claim keys; queue counts sum to 84,074 with no overlaps. | J4: Pass
A5: TC-004 | B5: Denial Insights | C5: §2.2 | D5: High | E5: Dashboard 'Latest Denial Analysis Report insights' shows the CURRENT week's insights | F5: Current week (Oct 14, 2026) has 1 uploaded Key Observation (CO-216) | G5: 1. Open Dashboard. 2. Compare insight list with Data Processing > Current week. | H5: Dashboard shows the same current-week insights as Data Processing, with description populated. | I5: Dashboard lists 5 system-generated codes (216, 252, 31, 27, 96) while Data Processing current week shows only the uploaded CO-216 insight. Dashboard Description column shows '—' for every row. | J5: Fail | K5: DEF-01, DEF-02
A6: TC-005 | B6: Denial Insights | C6: §2.2 | D6: Medium | E6: Data Processing shows current + previous week insights, unresolved items only | F6: Data Processing > Denial Analysis Report | G6: 1. Open Current week tab. 2. Open Previous week tab. 3. Check 'still open' counts. | H6: Two tabs (current & previous); counts reflect only unresolved / unassigned items. | I6: Current week (Oct 14) and Previous week (Sep 28) tabs present; open counts shown as 'X of Y'. Previous-week (system-generated) rows have Description '—' for all codes. | J6: Partial | K6: DEF-02
A7: TC-006 | B7: Denial Insights | C7: §2.2 | D7: High | E7: Clicking an insight routes to the filtered claim set in the Work Queue for bulk assignment | F7: Insight CO-216 (Still open 1,699) | G7: 1. Data Processing > Current week. 2. Click 'Route to Work Queue' on CO-216. | H7: Work Queue opens filtered to the insight's unassigned open claims; count equals insight's open count. | I7: Work Queue opened with filters Denial Code = CO-216, Workflow Status = Unassigned, Open AR only; 1,700 records returned vs 1,699 on the insight (1 claim carries 216 as a secondary code). | J7: Partial | K7: OBS-02
A8: TC-007 | B8: Denial Insights | C8: §2.2 | D8: Medium | E8: Insight counts cover all payers; Highest-impact payer is informational only | F8: Insight CO-216 | G8: 1. Compare # of denials vs. Ins. # of denials for top payer. | H8: Count and balance cover all payers; top payer is not used as a filter. | I8: CO-216: 2,051 denials / $714,194.50 across all payers; BCBS-MT shown as highest-impact payer (2,044) for information. Routing did not apply a payer filter. | J8: Pass
A9: TC-008 | B9: Denial Insights | C9: §2.2, AT-7, Feature #3 | D9: High | E9: Assigned claims are deducted from insight outstanding count/balance | F9: CO-216: 2,051 total; 10 already assigned | G9: 1. Read insight 'Still open'. 2. Independently recompute open, unassigned claims with primary denial 216. | H9: Insight shows only the unassigned remainder. | I9: Insight shows Still open 1,699 / $591,207.62. Independent recomputation: 1,699 open, unassigned claims with primary denial 216 (assigned claims excluded). | J9: Pass
A10: TC-009 | B10: Claim Detail | C10: §2.3 | D10: Medium | E10: Denial Info shows the claim's primary denial (code, description, category, classification) | F10: Claim 19448764 (curated denial 'CO11, CO252') | G10: 1. Open claim. 2. Open Denial Info tab. | H10: Primary code, description, category and classification populated. | I10: Primary Denial Code '11 (as received CO11)', Category 'Coding-Related Denials' shown. Denial Reason '—'; All Denial Codes '—' although claim carries CO11, CO252; Line-Level Codes rendered as '11252' (two codes concatenated without separator). | J10: Partial | K10: DEF-03
A11: TC-010 | B11: Claim Detail | C11: §2.3, Feature #4 | D11: Medium | E11: CPT Line-Level Detail has an expand control per CPT showing line-level denial code (prefix retained), description, classification | F11: Claim 19448764 (7 CPT lines) | G11: 1. Open CPT / Line Detail tab. 2. Look for expand control on each CPT. | H11: Each CPT row expandable; reveals line denial code with original prefix, description and classification. | I11: Line denials appear as an always-visible sub-row ('↳ Denial CO11 · Mar 24, 2026') — no expand control, no description/classification on this tab. Description and category are available in the separate 'Line-Level Denials' table under Denial Info. Prefix retained for display. | J11: Partial | K11: DEF-04
A12: TC-011 | B12: Claim Detail | C12: §2.3 | D12: Medium | E12: Line-level data does not drive queue placement | F12: Claim 19448764: lines Denied CO11/CO252 + 5 Partially Adjusted lines | G12: 1. Compare line statuses with claim AR Queue. | H12: Queue derived from claim-level primary denial only. | I12: Claim placed in Denied · Possible Collectible based on claim-level primary 11; line-level partial adjustments did not affect placement. | J12: Pass
A13: TC-012 | B13: AR Queue Logic | C13: §3.1, AT-1 | D13: High | E13: Closed – Fully Paid: Ins Bal = 0 and Pt Bal = 0; not fed to work queue | F13: All claims (API) | G13: 1. Check every Closed claim balance. 2. Check no zero-balance claim sits outside Closed. 3. Check queue is non-priority. | H13: All Closed – Fully Paid claims have zero balances; not in active work-queue feed. | I13: 42,502 claims; 0 with any balance; 0 zero-balance claims outside Closed; queue flagged non-priority (not auto-fed). | J13: Pass
A14: TC-013 | B14: AR Queue Logic | C14: §3.1 | D14: High | E14: Closed – Fully Adjusted: fully adjusted, no balance | F14: All claims (API) | G14: 1. Check balances of Closed – Fully Adjusted claims. | H14: Zero insurance and patient balance. | I14: 21,088 claims, all zero balance. | J14: Pass
A15: TC-014 | B15: AR Queue Logic | C15: §3.1, AT-2 | D15: High | E15: Non-Responder: Ins Bal > 0, no payment/denial/adjustment; auto-fed to work queue | F15: All claims (API) | G15: 1. Check Non-Responder claims for denial codes and balance. 2. Check priority flag. | H15: All have Ins Bal > 0 and no denial; queue is auto-fed. | I15: 2,627 claims; 0 with a denial code; 0 with zero Ins Bal; queue is priority (auto-fed). 2 claims have source status 'Patient Responsibility'. | J15: Pass | K15: OBS-03
A16: TC-015 | B16: AR Queue Logic | C16: §3.1, §4.1 | D16: High | E16: Denied – Possible Collectible: Ins Bal > 0, primary denial NOT on NC List | F16: NC List = 197, 242, 257, 288, 27, 31 | G16: 1. For each Denied PC claim, strip prefix from primary code and test against NC List. | H16: No Denied PC claim has an NC primary code. | I16: 4,280 claims; 0 with NC primary. 100 claims carry an NC/terminal code as a SECONDARY code in the curated column (e.g., 19509114 'PI5, PR242') and remain Possible Collectible — consistent with interim 'first code = primary' rule; terminal-denial override is Phase 2. | J16: Pass | K16: OBS-04
A17: TC-016 | B17: AR Queue Logic | C17: §3.1, §3.2, AT-3 | D17: High | E17: Denied – Non-Collectible: primary on NC List; visible only to Admin/Mgr/TL | F17: Primary 197 / 27 / 31 etc. | G17: 1. Verify placement via API. 2. Verify visibility as AR Agent / QA. | H17: Placed in Denied – Non-Collectible; hidden from Agent/QA. | I17: 751 claims placed correctly (all NC primary). Phase 2: ARAgent1 sees only its own 18 claims; NC queue query returns 0 and other claims 404 for the agent. Team Lead sees NC (749). QA Reviewer UI is blocked, but the claims API returns NC claims to QA (DEF-16). | J17: Partial | K17: DEF-16
A18: TC-017 | B18: AR Queue Logic | C18: §3.1 | D18: High | E18: Partially Paid – Possible Collectible / Non-Collectible split uses the same NC List | F18: All claims (API) | G18: 1. Check NC flag vs sub-queue. | H18: PC: primary not on NC List; NC: primary on NC List. | I18: 302 PC (0 NC primaries) / 8 NC (all NC primaries). | J18: Pass
A19: TC-018 | B19: AR Queue Logic | C19: §3.1 | D19: High | E19: Partially Adjusted: no denial, some CPTs adjusted, Ins Bal > 0 | F19: All claims (API) | G19: 1. Check denial code and balance on Partially Adjusted claims. | H19: No denial; Ins Bal > 0; auto-fed. | I19: 61 claims; 0 with denial; all Ins Bal > 0; priority queue. | J19: Pass
A20: TC-019 | B20: AR Queue Logic | C20: §3.1, AT-6 | D20: High | E20: Patient AR: Pt Bal > 0 and Ins Bal = 0; denials ignored | F20: All claims (API) | G20: 1. Check all Patient AR claims. 2. Check no Pt-only-balance claim outside Patient AR. | H20: All Patient AR claims meet rule; none misplaced, even when a denial is present. | I20: 11,349 claims, all Pt Bal > 0 & Ins Bal = 0; 0 misplaced. None of these claims carries a denial code in the claim data, so 'denial present' variant could not be exercised. | J20: Pass | K20: OBS-05
A21: TC-020 | B21: AR Queue Logic | C21: §3.1, Features #7, #8 | D21: High | E21: Workflow queues exist: CIP Pending, CIP Response Received, Re-Follow-Up (Unresolved / New Denials), Submitted for QA, QA Rejected, Completed, Auto Adjustments | F21: Queue taxonomy (queues API) | G21: 1. Review queue list. | H21: All workflow queues and sub-queues defined. | I21: All present, incl. Re-Follow-Up → Unresolved Claims / New Denials and Auto Adjustments → System Auto-Adjusted / Approved Write-Offs – Pending Posting. Extra queues not in spec: 'Unbilled (Not Yet Billed)' (1,102) and 'Status Change Verification'. | J21: Pass | K21: OBS-06
A22: TC-021 | B22: AR Queue Logic | C22: §3.2 | D22: High | E22: Only unresolved claims in the 4 Possible Collectible queues auto-flow into the Work Queue for assignment | F22: Nav badge 'Denial & AR Work Queue' = 9,054; Dashboard 'Claims Awaiting Assignment' = 83,986 | G22: 1. Reconcile unassigned counts by queue. 2. Compare with badge and dashboard KPI. | H22: Awaiting-assignment count = unassigned claims in Non-Responder, Denied PC, Partially Paid PC, Partially Adjusted only (7,193). | I22: Badge 9,054 = 7,193 PC + 759 Non-Collectible (751 Denied + 8 Partially Paid) + 1,102 Unbilled. Dashboard KPI 'Claims Awaiting Assignment' = 83,986 counts every unassigned claim, including 63,583 Closed and 11,349 Patient AR. | J22: Fail | K22: DEF-05, DEF-06
A23: TC-022 | B23: Configuration | C23: §3.2, Feature #2 | D23: High | E23: Non-Collectible list maintained in settings and drives the Denied & Partially Paid splits | F23: Master Values > Workbench Lists > Non-Collectible Denial Codes | G23: 1. Open list. 2. Compare with Denial Code Master 'Non-Collectible' flags. | H23: Single configurable NC list, stored without prefix, used by the queue engine. | I23: Workbench list (6 codes: 197, 242, 257, 288, 27, 31) is maintainable and used by the queue engine. However, Denial Code Master flags a DIFFERENT set of 8 NC codes (29, 119, 193, 197, 204, 242, 243, 279) with an 'Apply Non-Collectible codes' action — two conflicting sources. | J23: Partial | K23: DEF-07
A24: TC-023 | B24: Roles & Access | C24: §10 (Maintain NC & Auto-Adjust lists) | D24: Medium | E24: AR/RCM Manager can maintain NC and Auto-Adjust lists | F24: App navigation role config | G24: 1. Inspect role access for Master Values. | H24: Sys Admin and AR/RCM Manager can maintain. | I24: Master Values (incl. Workbench Lists) is restricted to System Administrator only ('Administrators only'); RCM Manager has no access. | J24: Fail | K24: DEF-08
A25: TC-024 | B25: Roles & Access | C25: §3.2, AT-3 | D25: High | E25: Restricted (overall AR) queues visible only to Admin / Mgr / TL; they can pull any claim for special projects | F25: Admin session | G25: 1. As Admin, view all queues and assign. 2. As Agent/QA, confirm restricted queues hidden. | H25: Admin/Mgr/TL see and assign from any queue; Agent/QA cannot see Closed / NC queues. | I25: Admin, RCM Manager and Team Lead see and assign from all queues (TL: 84,074 claims incl. 749 NC / 21,090 Closed-Adjusted). AR Agent restricted server-side to own claims. QA Reviewer: Work Queue page blocked, but claims API returns all 84,074 claims incl. restricted queues. | J25: Partial | K25: DEF-16
A26: TC-025 | B26: AR Queue Logic | C26: §3.2 | D26: High | E26: QA Rejected claims auto-assigned to the agent who worked them | F26: Claim 19091270 | G26: 1. Open claim timeline and assignment fields. | H26: Rejected claim assigned back to the submitting agent. | I26: Submitted by ARAgent1, rejected by QA1 (Financial Update Error); AssignedAgentUser = ARAgent1. Note: work-queue API returns AssignedAgentName = null for this claim. | J26: Pass | K26: OBS-07
A27: TC-026 | B27: AR Queue Logic | C27: §3.2 (To confirm) | D27: Low | E27: Evaluation precedence when a claim meets more than one rule | F27: All claims | G27: 1. Check for claims meeting multiple rules. | H27: Deterministic precedence (recommended Closed → Patient AR → Denied → Partially Paid → Partially Adjusted → Non-Responder). | I27: No claim found in more than one queue; precedence behaviour consistent with recommended order in observed data. Formal precedence still an open item (#4). | J27: Pass
A28: TC-027 | B28: Denial Logic | C28: §4.1 | D28: High | E28: Primary denial = curated 'Denial Code' column (interim) | F28: Settings API | G28: 1. Read settings PrimaryDenialSource / FallbackToLine. | H28: Curated column used; no line-level fallback. | I28: PrimaryDenialSource = CuratedColumn; PrimaryDenialFallbackToLine = 0. | J28: Pass
A29: TC-028 | B29: Denial Logic | C29: §4.1, Feature #15 | D29: Low | E29: Denial-hierarchy ranking table to derive primary denial (terminal codes override) | F29: — | G29: — | H29: Configurable ranking table; e.g., 204/197 override other codes. | I29: Phase 2 — awaiting mapping from business owner. Not tested. | J29: N/A (Phase 2)
A30: TC-029 | B30: Denial Logic | C30: §4.2, AT-4, Feature #5 | D30: High | E30: CARC group prefix (CO/PR/PI/OA) stripped for mapping | F30: PR204 (25 claims), CO204 (13 claims); PRA1, PIB11 | G30: 1. Compare category for prefixed variants of the same code. | H30: PR 204 and CO 204 both map to 204 and the same category. | I30: PR204 and CO204 both → 204 → Medical Necessity. PRA1→A1, PIB11→B11, COB12→B12 normalised correctly. 'CR96' (CR group) is not stripped and lands in Unmapped/'Other' while CO/PR/PI96 map to Medical Necessity. | J30: Pass | K30: OBS-08
A31: TC-030 | B31: Denial Logic | C31: §4.2, AT-5 | D31: Medium | E31: RARC codes keep their letter (e.g., N57, M127, MA130) | F31: Claim data and Denial Code Master | G31: 1. Search for N57 / RARC codes. | H31: Stored and mapped as N57 (letter retained). | I31: No N57 / M127 / MA130 in claim data or Denial Code Master. Only RARC-style code found, N857 (4 claims), is retained as 'N857' but is unmapped. Test data needed. | J31: Blocked | K31: Test data
A32: TC-031 | B32: Denial Logic | C32: §4.3 | D32: High | E32: Denial categorization for all denial codes loaded into the Denial-Action master | F32: Workbench Category Map / Unmapped Codes | G32: 1. Review category map coverage. 2. Review Unmapped Codes. | H32: Every primary denial code on synced claims has a category. | I32: Only 36 codes mapped; 50 primary codes unmapped (incl. 216 – 1,708 claims / $594,638.84; A1 – 222 claims). 2,534 of 5,280 denied claims (48%) fall to 'Other'. Depends on open item #2 (categorization from business owner). | J32: Fail | K32: DEF-09
A33: TC-032 | B33: Denial Logic | C33: §4.2 | D33: Low | E33: Line-level display keeps original prefix but is not used for mapping | F33: Claim 19448764 | G33: 1. View line-level denials. | H33: Prefixed value shown; mapping uses stripped code. | I33: Lines show CO11 / CO252; claim maps on stripped 11. | J33: Pass
A34: TC-033 | B34: Weekly Re-Sync | C34: §5, AT-10 | D34: High | E34: Assigned, not-yet-worked claim whose denial changes: update silently; if new primary is NC, auto-process and remove from agent queue | F34: Requires a sync with changed denial data | G34: 1. Assign claim. 2. Load sync file with new (NC) denial. 3. Check agent queue. | H34: Denial updated without reassignment; NC claim auto-processed and removed. | I34: Not executed — needs a controlled re-sync. App has a 'Status Change Verification' queue for claim-STATUS changes on assigned claims (not in spec). | J34: Not Executed | K34: OBS-06
A35: TC-034 | B35: Weekly Re-Sync | C35: §5, AT-9, Feature #7 | D35: High | E35: Worked claim (QA/Completed/QA Rejected) receives a new denial → after QA completes, moves to Re-Follow-Up – New Denials, unassigned, history intact | F35: Requires a sync with a new denial on a completed claim | G35: 1. Complete claim. 2. Re-sync with new denial. | H35: Claim in Re-Follow-Up – New Denials, unassigned, full history. | I35: Queue exists (0 claims). Not executed — needs controlled re-sync. | J35: Not Executed
A36: TC-035 | B36: Weekly Re-Sync | C36: §5, §3.1 | D36: High | E36: Followed-up claim with no reply/action for 45 days → Re-Follow-Up – Unresolved Claims | F36: RefollowupDays = 45 | G36: 1. Identify claims with last touch ≥ 45 days. | H36: Claims ≥ 45 days since last touch appear in Unresolved queue. | I36: Setting = 45. Earliest follow-up in system is Oct 07, 2026, so no claim qualifies yet. Assignment page separately lists '6,066 claims untouched for 45+ days' — these are never-worked claims, which by spec are not Re-Follow-Up. | J36: Blocked | K36: OBS-09
A37: TC-036 | B37: Weekly Re-Sync | C37: §5, §6, AT-12, Feature #9 | D37: High | E37: Auto-adjusted / approved write-off claim still open on next sync → flagged, returned to Auto Adjustments, agent & manager notified | F37: Requires processed auto-adjustment + re-sync | G37: 1. Process auto adjustment. 2. Re-sync with claim still open. | H37: Flag + return + notification. | I37: Setup done: 19510788 auto-adjusted and intentionally left NOT posted for the next sync. Re-sync verification pending (next weekly sync). | J37: Not Executed | K37: Next sync
A38: TC-037 | B38: Weekly Re-Sync | C38: §5 | D38: Medium | E38: Claim that now meets closed criteria moves to the relevant Closed queue | F38: Claims 19448701, 19446019, 19445909, 19454954, 19449830, 19449723, 19449752 | G38: 1. Check workflow status of Closed claims. | H38: Claim in Closed queue; recovered amount recognised. | I38: Closed placement correct. 7 Closed claims remain 'Assigned' to agents — acceptable only if intentionally assigned for a special project; confirm. | J38: Partial | K38: OBS-10
A39: TC-038 | B39: Auto Adjustments | C39: §6 | D39: High | E39: Auto-Adjust code list is configurable | F39: Workbench Lists > Auto-Adjust Denial Codes | G39: 1. Open list. | H39: List maintainable; seeded with 242, 197. | I39: 2 active codes: 242, 197; add/deactivate available (admin). | J39: Pass
A40: TC-039 | B40: Auto Adjustments | C40: §6, Feature #8 | D40: High | E40: Process Auto Adjustment: adds system comment, nullifies balance, moves claims to Auto Adjustments queue | F40: Work Queue > Process Automatic Adjustments | G40: 1. Run preview / process on matching claims. | H40: Claims moved to Auto Adjustments (not Completed) with system comment and $0 balance. | I40: Admin selected 19122637 (CO197) → preview '1 non-collectible denial totaling $60.90' → processed; 19510788 (PR242) processed ($228.86). Both moved to Auto Adjustments › System Auto-Adjusted with system comment 'insurance balance … adjusted automatically for denial 197'; RemainingAR = 0, Recovery Status 'No Recovery'. InsuranceBalance field still shows $60.90. | J40: Pass | K40: DEF-20
...

Sheet Role Workflow Tests
A1: Step ID | B1: Role | C1: Login | D1: Scenario / Requirement | E1: Claim(s) | F1: Action Performed | G1: Expected Result | H1: Actual Result | I1: Status | J1: Defect Ref
A2: RW-01 | B2: System Administrator | C2: ARWBInhealthSA | D2: Assign claims with optional due date (§8.5) | E2: 19538684 + 6 others | F2: Work Queue › search › select › Assign Selected → ARAgent1, due 20-Oct, note | G2: Claims assigned; due date optional | H2: '1 assigned — ARAgent1.'; other 6 assigned via same service; status Assigned | I2: Pass
A3: RW-02 | B3: System Administrator | C3: ARWBInhealthSA | D3: Process Automatic Adjustment on selected claims (§6) | E3: 19122637, 19510788 | F3: Select claim › Process Automatic Adjustments › confirm | G3: Only selected claims adjusted; moved to Auto Adjustments with system comment | H3: Preview showed only the selected claim ($60.90); processed → Auto Adjustments › System Auto-Adjusted; system comment added; RemainingAR 0; InsuranceBalance field unchanged | I3: Pass | J3: DEF-20
A4: RW-03 | B4: System Administrator | C4: ARWBInhealthSA | D4: Export Auto Adjustments queue (§6) | E4: — | F4: AR Queue filter = Auto Adjustments › Export Filtered | G4: Excel report of the queue | H4: 2 claims listed; .xlsx returned | I4: Pass | J4: OBS-11
A5: RW-04 | B5: AR Agent | C5: ARAgent1 | D5: Agent sees only own work; restricted queues hidden (§3.2, §10) | E5: — | F5: Open Work Queue; probe NC/Closed queues, other claim, assign & QA endpoints | G5: Own claims only; no assign/QA | H5: 18 own claims; NC/Closed = 0; other claim 404; assign 403; QA 403; no Assign / Auto-Adjust buttons | I5: Pass
A6: RW-05 | B6: AR Agent | C6: ARAgent1 | D6: Log follow-up → Submitted for QA (§8.1) | E6: 19144266 | F6: Claim Status Denied, Fix 'Appealed', comment; default next date | G6: Routed to QA; next date = today + 45 | H6: 'sent to the QA Verification Queue'; Next follow-up 29-Nov-2026 | I6: Pass
A7: RW-06 | B7: AR Agent | C7: ARAgent1 | D7: Write-off submission (§8.3) | E7: 19521528 | F7: Fix 'Write Off' › Save | G7: Submitted for QA as write-off | H7: Submitted for QA; QA KPI 'Write-offs pending review' = 1 | I7: Pass
A8: RW-07 | B8: AR Agent | C8: ARAgent1 | D8: CIP escalation with mandatory CIP comment (§9.1) | E8: 19524452, 19490126 | F8: Fix 'CIP - Client Escalations'; save without CIP comment, then with | G8: Blocked without CIP comment; then routed to QA | H8: 'Add the CIP comment the client will see.'; after entry → Submitted for QA | I8: Pass
A9: RW-08 | B9: AR Agent | C9: ARAgent1 | D9: Escalate to Supervisor with mandatory reason (§8.4) | E9: 19404713 | F9: Escalate without reason, then with 'Payer portal access required' | G9: Reason mandatory; request raised | H9: 'Choose a reason.'; then 'escalated to a supervisor' | I9: Pass
A10: RW-09 | B10: AR Agent | C10: ARAgent1 | D10: Request Reassignment with reason (§8.4) | E10: 19465060 | F10: Reason 'Payer call outside my shift' + note | G10: Request raised; claim stays with agent | H10: 'Reassignment requested… stays with you until a lead reassigns it.' | I10: Pass
A11: RW-10 | B11: QA Reviewer | C11: QA1 | D11: QA reject → back to same agent (§3.2) | E11: 19538684 | F11: Reject: Error Type 'Incomplete Documentation', scoring, note | G11: QA Rejected, assigned to ARAgent1 | H11: 'returned to the same agent under QA Rejected'; AssignedAgent ARAgent1 | I11: Pass
A12: RW-11 | B12: QA Reviewer | C12: QA1 | D12: QA approve normal / write-off / CIP (§8.3, §9.1) | E12: 19144266, 19521528, 19524452, 19490126 | F12: Approve each | G12: Completed / Approved Write-Offs Pending Posting / CIP Pending Approval | H12: 19144266 Completed; 19521528 → Approved Write-Offs – Pending Posting; both CIPs → Pending Approval | I12: Pass
A13: RW-12 | B13: QA Reviewer | C13: QA1 | D13: QA role limits (§10) | E13: — | F13: Open Work Queue page; probe assign/CIP/masters/claims APIs | G13: No work-queue / restricted data | H13: UI: 'cannot open Work Queue'; assign/CIP/masters 403; BUT claims API returns 84,074 incl. 749 NC | I13: Partial | J13: DEF-16
A14: RW-13 | B14: AR Agent | C14: ARAgent1 | D14: Write-off approval notification & posting (§8.3, AT-11) | E14: 19521528 | F14: Check notifications/My Work; try Mark as Posted | G14: Notification + pending-posting item; agent marks posted | H14: Notification received; item in My Work; Mark as Posted not available (403) | I14: Partial | J14: DEF-17
A15: RW-14 | B15: AR Agent | C15: ARAgent1 | D15: Rework QA-rejected claim | E15: 19538684 | F15: View QA Review tab; log corrected follow-up | G15: QA feedback visible; resubmitted | H15: Error type, notes and scoring visible; resubmitted to QA | I15: Pass
A16: RW-15 | B16: Team Lead | C16: TeamLead | D16: Bulk QA approve (§9.1 QA by TL) | E16: 19538684 | F16: QA › select › Approve Selected | G16: Approved; self-work guard | H16: '1 approved.'; dialog notes own-work claims skipped | I16: Pass
A17: RW-16 | B17: Team Lead | C17: TeamLead | D17: Bulk CIP second approval (§9.1) | E17: 19524452, 19490126 | F17: CIP Escalations › select both › Bulk Approve | G17: Sent to client | H17: '2 sent to the client.' Status Sent to Client | I17: Pass
A18: RW-17 | B18: Team Lead | C18: TeamLead | D18: Respond to escalation; reassign on request (§8.4) | E18: 19404713, 19465060 | F18: Respond › Mark Resolved; Reassign & Resolve → ARAgent3 | G18: Escalation resolved; claim reassigned, request closed | H18: Both resolved; audit 'Reassigned from ARAgent1 to ARAgent3' | I18: Pass
A19: RW-18 | B19: Team Lead | C19: TeamLead | D19: Mark write-off / auto-adjustment as posted (§6, §8.3) | E19: 19521528, 19122637 | F19: Select › Mark as Posted | G19: Posted; claim closes | H19: '1 claim(s) marked as posted'; 19521528 → Closed – Fully Adjusted | I19: Pass
A20: RW-19 | B20: Team Lead | C20: TeamLead | D20: Restricted queue visibility; masters access (§3.2, §10) | E20: — | F20: Query NC/Closed; open Master Values | G20: Sees restricted queues; cannot maintain lists | H20: NC 749 / Closed 21,090 visible; masters 403 | I20: Pass
A21: RW-20 | B21: Clinic Viewer | C21: ClinicViewer (Insight Family Practice) | D21: Clinic scope & CIP routing (§10.1, AT-14) | E21: 19524452 vs 19490126 | F21: Open Escalation Requests; probe other-clinic claim | G21: Only own clinic data and CIPs | H21: Only CIP-000002; 7,300 claims all Insight Family Practice; other clinic claim 404 | I21: Pass
A22: RW-21 | B22: Clinic Viewer | C22: ClinicViewer (Insight Family Practice) | D22: Client never sees internal notes (§9.2) | E22: 19524452 | F22: Open #/claims/30117 directly; Follow-Ups / Activity / QA tabs | G22: Internal notes hidden | H22: Internal agent note and QA notes visible | I22: Fail | J22: DEF-15
A23: RW-22 | B23: Clinic Viewer | C23: ClinicViewer (Insight Family Practice) | D23: Clinic user responds to CIP (§9.1, §10.1) | E23: 19524452 | F23: Open request | G23: Respond with info/attachments | H23: Read-only: 'the client contact responds'; no Respond | I23: Fail | J23: DEF-18
A24: RW-23 | B24: Client Viewer | C24: AccountManager | D24: Client responds with attachment; size limit (§9.1, AT-16) | E24: 19524452 | F24: Attach 16 MB file; submit empty; submit text + PDF | G24: 16 MB rejected; text required; response accepted | H24: 'larger than 15 MB'; 'Enter the requested information.'; 'Response submitted… with 1 attachment(s)' | I24: Pass
A25: RW-24 | B25: Client Viewer | C25: AccountManager | D25: Client never sees internal notes (§9.2) | E25: 19524452 | F25: Claim API / page | G25: Hidden | H25: Internal notes returned | I25: Fail | J25: DEF-15
A26: RW-25 | B26: RCM Manager | C26: RCMManager | D26: Review client response → insufficient → re-escalate (§9.1) | E26: 19524452 | F26: Review Response › Insufficient (no note, then note) | G26: Note mandatory; client gets round 2 with feedback | H26: 'Add a reason first.'; re-sent; client sees Round 2 + 'Needs more info' feedback | I26: Pass | J26: DEF-19
A27: RW-26 | B27: RCM Manager | C27: RCMManager | D27: Reassign claim (§10) | E27: 19404713 | F27: Assign → ARAgent3 with due date | G27: Reassigned | H27: '1 reassigned — ARAgent3.'; audit entry | I27: Pass
A28: RW-27 | B28: RCM Manager | C28: RCMManager | D28: Maintain NC / Auto-Adjust lists (§10) | E28: — | F28: Open Workbench Lists | G28: Allowed | H28: 'cannot open Workbench Lists'; API 403 | I28: Fail | J28: DEF-08
A29: RW-28 | B29: RCM Manager | C29: RCMManager | D29: Audit trail & progress monitoring (§10, project scope) | E29: — | F29: Audit Logs; Dashboard Agent Productivity | G29: All actions logged; progress by agent | H29: 244 audit entries incl. every UAT action; ARAgent1 16 assigned / 6 completed | I29: Pass
A30: RW-29 | B30: Client Viewer | C30: AccountManager | D30: Second-round response (§9.1) | E30: 19524452 | F30: Respond again with signed requisition PDF | G30: Accepted | H30: 'Response submitted… 1 attachment(s)' | I30: Pass
A31: RW-30 | B31: RCM Manager | C31: RCMManager | D31: Approve client response → returns to original agent (§9.1, AT-13) | E31: 19524452 | F31: Review Response › Approve & Return to Agent | G31: Claim auto-returns to ARAgent1 | H31: 'response approved - the claim is back with the AR agent'; Assigned to ARAgent1; queue CIP Response Received; both attachments retained | I31: Pass

Sheet Defect Log
A1: Defect ID | B1: Linked Test Case(s) | C1: Area | D1: Severity | E1: Description | F1: Status
A2: DEF-01 | B2: TC-004 | C2: Dashboard | D2: High | E2: Dashboard insights panel does not show the current week's uploaded Key Observations; shows system-generated top-5 list instead (216, 252, 31, 27, 96) while Data Processing current week shows only CO-216. | F2: Open
A3: DEF-02 | B3: TC-004, TC-005 | C3: Dashboard / Data Processing | D3: Medium | E3: Denial code Description shows '—' on Dashboard and on system-generated insight rows although the Denial Code Master holds descriptions (e.g., 216). | F3: Deferred
A4: DEF-03 | B4: TC-009 | C4: Claim Detail > Denial Info | D4: Medium | E4: Denial Reason and 'All Denial Codes' empty for claim with curated 'CO11, CO252'; 'Line-Level Codes' renders '11252' (codes concatenated without separator). | F4: Open
A5: DEF-04 | B5: TC-010 | C5: Claim Detail > CPT / Line Detail | D5: Low | E5: No per-CPT expand control; line denial sub-row lacks description and classification (only on Denial Info tab). | F5: Open
A6: DEF-05 | B6: TC-021 | C6: Work Queue feed | D6: High | E6: Work-queue feed / nav badge (9,054) includes Non-Collectible (759) and Unbilled (1,102) claims; spec limits auto-feed to the 4 Possible Collectible queues (7,193). | F6: Open
A7: DEF-06 | B7: TC-021 | C7: Dashboard KPI | D7: High | E7: 'Claims Awaiting Assignment' (83,986) counts every unassigned claim incl. Closed and Patient AR; should count only open Possible Collectible claims. | F7: Open
A8: DEF-07 | B8: TC-022 | C8: Configuration | D8: High | E8: Two conflicting Non-Collectible sources: Workbench list (197, 242, 257, 288, 27, 31) vs Denial Code Master flags (29, 119, 193, 197, 204, 242, 243, 279). Queue engine uses Workbench list; 204/29 etc. treated as collectible. | F8: Open
A9: DEF-08 | B9: TC-023, TC-064 | C9: Roles & Access | D9: Medium | E9: RCM Manager cannot maintain NC / Auto-Adjust lists — Master Values is admin-only. | F9: Open
A10: DEF-09 | B10: TC-031 | C10: Denial categorization | D10: High | E10: 50 primary denial codes unmapped (incl. 216 – 1,708 claims / $594.6K); 48% of denied claims categorised 'Other'. Dependent on open item #2. | F10: Deferred
A11: DEF-10 | B11: TC-041 | C11: Work Queue grid | D11: Low | E11: Column header still 'Expected Payment'; should read 'Revenue Expectation'. | F11: Open
A12: DEF-11 | B12: TC-042, TC-043, TC-044 | C12: Financial fields | D12: High | E12: Revenue Expectation = $0 on all claims (no fee schedule loaded) so Potential Recovery / Recovery Status cannot work; dashboard 'revenue expectation' uses Initial Insurance AR instead. Dependent on open item #5. | F12: Open – dependency
... A21: DEF-20 | B21: TC-039 | C21: Auto Adjustments | D21: Low | E21: After auto-adjustment, RemainingAR = 0 but claim InsuranceBalance still shows the original amount (19122637: $60.90). §6 says nullify the balance within the Workbench. | F21: Open

Sheet Observations
A1: Obs ID | B1: Linked Test Case(s) | C1: Observation / Clarification Needed
A2: OBS-01 | B2: TC-001 | C2: Data Processing header 'Master File Loaded' shows '—' even though run #3 loaded a file.
A3: OBS-02 | B3: TC-006 | C3: Insight count (1,699) uses primary denial only; routed Work Queue filter returns 1,700 (includes a claim with 216 as secondary code). Align filter with insight basis.
A4: OBS-03 | B4: TC-014 | C4: 2 Non-Responder claims have source status 'Patient Responsibility' — confirm intended.
A5: OBS-04 | B5: TC-015 | C5: 100 Denied – Possible Collectible claims carry an NC/terminal code (e.g., 242) as a secondary code in the curated column; will move once Phase 2 hierarchy is delivered.
A6: OBS-05 | B6: TC-019 | C6: No Patient AR claim retains a denial code, so 'denial present → still Patient AR' could not be exercised.
A7: OBS-06 | B7: TC-020, TC-033 | C7: Extra queues not in spec: 'Unbilled (Not Yet Billed)' and 'Status Change Verification'. Confirm with business owner and add to the requirement doc.
A8: OBS-07 | B8: TC-025 | C8: Claims API returns AssignedAgentName = null while AssignedAgentUser is populated (display name gap).
A9: OBS-08 | B9: TC-029 | C9: 'CR' (Corrections & Reversals) group prefix not stripped — CR96 falls to Unmapped/'Other'. Spec lists CO/PR/PI/OA only; confirm whether CR should be added.
A10: OBS-09 | B10: TC-035 | C10: Assignment page '6,066 claims untouched for 45+ days' counts never-worked claims; ensure this is not confused with the Re-Follow-Up – Unresolved rule (touched claims only).
A11: OBS-10 | B11: TC-037 | C11: 7 Closed claims remain 'Assigned' — confirm they were assigned intentionally (special project) rather than left assigned after closing on sync.
A12: OBS-11 | B12: TC-040 | C12: No dedicated 'Export Auto Adjustments report' for PMS posting; relies on generic export.
... A16: OBS-15 | B16: RW (all) | C16: 1,165 unassigned Possible Collectible claims have no clinic on the claim, so clinic-scoped users will never see them; confirm clinic mapping in the master file.

Sheet Mockup Comparison
A1: Ref | B1: Area | C1: Mockup (Demo Account HTML) | D1: Application (Test) | E1: Assessment
A2: M-01 | B2: Navigation / screens | C2: 16 screens incl. My Work, System Settings, Client Escalation Requests (viewer) | D2: All screens present; 'System Settings' replaced by 'Master Values' (9 sub-pages); adds 'Status Change Verification' | E2: Aligned (with additions)
A3: M-02 | B3: Personas / roles | C3: Admin, RCM Manager, Team Lead, AR Agent, QA Reviewer, Client Viewer (client / clinic / provider scopes) | D3: Same 8 roles incl. Clinic Viewer and Provider Viewer | E3: Aligned
A4: M-03 | B4: Dashboard KPI tiles | C4: 10 tiles: Eligible Claims, Outstanding Ins AR, Awaiting Assignment, In Progress, Awaiting QA, QA Rejected, Completed/Closed, Recovered, Potential Recovery, Overdue Follow-Ups | D4: Same 10 tiles | E4: Aligned (values: see DEF-06, DEF-11)
A5: M-04 | B5: Dashboard insight table | C5: Denial code, description, counts, balance, top payer, impact, observation, category, action | D5: Same columns; descriptions blank | E5: Partially aligned (DEF-02)
A6: M-05 | B6: Work Queue filters | C6: Client, payer, panel, category, status, agent, priority, aging, AR queue, TFL, search, saved views | D6: Same plus Clinic, Open Ins AR only, Non-collectible only | E6: Aligned
A7: M-06 | B7: Work Queue column | C7: 'Expected Payment' | D7: 'Expected Payment' (mockup pre-dates handoff rename) | E7: Both outdated vs handoff (DEF-10)
A8: M-07 | B8: Claim detail financials | C8: Expected Payment, Potential Recovery | D8: Revenue Expectation, Potential Recovery, Recovery Status | E8: App follows handoff (better than mockup)
A9: M-08 | B9: Process Automatic Adjustments | C9: Button in restricted Work Queue; claims moved to Completed | D9: Button present; Auto Adjustments queue created (per handoff) | E9: App follows handoff
A10: M-09 | B10: Log Follow-Up Note | C10: Claim Type, Follow-Up Type, Claim Status, Root Cause, Fix/Resolution, Comment, Next Follow-Up | D10: Same fields + CIP Category / Required Info / CIP Comment | E10: Aligned; neither has attachments (DEF-13)
A11: M-10 | B11: CIP Escalations | C11: Review, bulk approve / reject, return to agent, re-escalate | D11: Same lifecycle and bulk actions | E11: Aligned
A12: M-11 | B12: Escalation & Reassignment Requests | C12: Screen for Admin/Mgr/TL with Mark Resolved | D12: Same; reassigning resolves request | E12: Aligned
... A16: M-15 | B16: Document Vault | C16: Not in mockup | D16: Not built | E16: Gap vs handoff (DEF-14)

Sheet Queue Reconciliation
A1: Queue reconciliation – all 84,074 claims (API pull, 15 Oct 2026)
A3: Queue | B3: Sub-queue | C3: Claims | D3: Unassigned | E3: Auto-fed per spec? | F3: Rule exceptions found
A4: Closed | B4: Fully Paid | C4: 42502 | D4: 42502 | E4: No | F4: 0
A5: Closed | B5: Fully Adjusted | C5: 21088 | D5: 21081 | E5: No | F5: 0
A6: Patient AR | B6: — | C6: 11349 | D6: 11349 | E6: No | F6: 0
A7: Non-Responder | B7: Possible Collectible | C7: 2627 | D7: 2622 | E7: Yes | F7: 0
A8: Denied | B8: Possible Collectible | C8: 4280 | D8: 4220 | E8: Yes | F8: 0
A9: Denied | B9: Non-Collectible | C9: 751 | D9: 751 | E9: No | F9: 0
A10: Partially Paid | B10: Possible Collectible | C10: 302 | D10: 290 | E10: Yes | F10: 0
A11: Partially Paid | B11: Non-Collectible | C11: 8 | D11: 8 | E11: No | F11: 0
A12: Partially Adjusted | B12: Possible Collectible | C12: 61 | D12: 61 | E12: Yes | F12: 0
A13: Unbilled (not in spec) | B13: — | C13: 1102 | D13: 1102 | E13: Not defined | F13: 0
A14: QA Rejected | B14: — | C14: 1 | D14: 0 | E14: — | F14: 0
A15: Client Escalation (CIP) Pending | B15: — | C15: 1 | D15: 0 | E15: — | F15: 0
A16: Completed Claims | B16: — | C16: 2 | D16: 0 | E16: — | F16: 0
A17: Total | C17: =SUM(C4:C16) -> 84074 | D17: =SUM(D4:D16) -> 83986
A19: Unassigned in spec auto-fed queues | D19: =SUMIFS(D4:D16,E4:E16,"Yes") -> 7193
A20: Work Queue nav badge (observed in app) | D20: 9054
A21: Variance (badge − spec) | D21: =D20-D19 -> 1861
A22: Dashboard 'Claims Awaiting Assignment' (observed) | D22: 83986
A23: Blue values were read from the app UI on 15 Oct 2026; counts in the table come from the claims API pull.
